<!DOCTYPE html>
<html lang="en">
  <head>
    <meta charset="UTF-8" />
    <meta name="viewport" content="width=device-width, initial-scale=1.0" />
    <title>Promise</title>
  </head>
  <body>
    <script>
      /* 
      1. 是什么？
        解决异步回调地狱的方案
      2. 如何创建promise对象
        new Promise((resolve, reject) => {})  
          默认状态是pending状态
          调用resolve会改成 resolved / fulfilled 状态
          调用reject会改成 rejected 状态  
          注意：状态只能修改一次

          调用resolve、reject可以传参，传入的参数就会作为promise对象的结果值
      
          通过 then / catch 来捕获promise对象的状态，看到底是成功还是失败
            成功会触发then方法的第一个回调函数
            失败会触发catch方法/then方法的第二个回调函数
              这些回调函数就能接收到之前resolve、reject传递结果值

        Promise.resolve() 创建成功、失败的promise
        Promise.reject()  创建失败的Promise
        Promise.all([promise1, promise2, ]) 
          等传入promise对象都成功才返回成功的promise， 
          只要有一个失败，就返回失败的promise， 
        Promise.allSettled([promise1, promise2, ])   
          等传入promise对象状态都发生变化时，会返回一个成功的promise
    */

      // console.log(111);

      const promise = new Promise((resolve, reject) => {
        // resolve("success");
        setTimeout(() => {
          resolve(111);
        }, 2000);
        // 同步调用
        // console.log(222);
      });

      promise
        /*
          then返回值是一个新的promise1对象，
            他的状态看里面函数调用的返回值：
              如果返回值是一个promise2对象，那么这个promise2的状态是什么，promise1的状态就是什么
              如果返回值不是promise对象，或者没有返回值，那么promise1对象默认是成功状态
              如果函数调用报错了，那么promise1对象就会是失败状态
        */
        .then(
          (value) => {
            console.log("111success", value);

            throw new Error("错误");
            // return {};
            // return new Promise((resolve) => {
            //   reject();
            // });
          },
          (reason) => {
            console.log("111error", reason);
          }
        )
        .then(
          (value) => {
            console.log("222success", value);
          },
          (reason) => {
            console.log("222error", reason);
          }
        );
      // console.log(333);

      // const p = Promise.resolve(111);

      // const p = Promise.resolve(
      //   new Promise((resolve, reject) => {
      //     // resolve(111);
      //     reject(111);
      //   })
      // );

      // const p = Promise.reject(
      //   new Promise((resolve, reject) => {
      //     resolve(111);
      //     // reject(111);
      //   })
      //   // 111
      // );

      const a = new Promise((resolve, reject) => {
        setTimeout(() => {
          // resolve("aaa");
          reject("aaa");
        }, 1000);
      });

      const b = new Promise((resolve) => {
        setTimeout(() => {
          resolve("bbb");
        }, 2000);
      });

      Promise.all([a, b, a, {}])
        .then((value) => {
          console.log("success", value);
        })
        .catch((reason) => {
          console.log("error", reason);
        });

      // console.log(p);
    </script>
  </body>
</html>
